Workbook

Sheet 2.4.1.1.
A1: Ümumi Daxili Məhsul (real artım tempi, deflyatoru, neft-qaz və qeyri neft-qaz sektorunun payı, onların real artım tempi və deflyatoru)
A2: № | B2: Göstəricilər | C2: ASİS-də olan ad | D2: Ölçü vahidi | G2: Mənbə / qeyd
E3: 2024 | F3: 2030
A4: 1. | B4: ÜDM bazar qiymətləri ilə | C4: Ümumi daxili məhsul (bazar qiymətləri ilə) | D4: mln AZN | E4: ='[1]ÜDM sahələr üzrə'!AI5 -> 126337.01 | F4: ='[1]ÜDM sahələr üzrə'!AO5 -> 168392.95 | G4: DSK (stat.gov.az / ASİS)
B5: real artım tempi | C5: Real artım tempi | D5: % | E5: ='[1]ÜDM sahələr üzrə'!AI6 -> 4.0660314 | F5: ='[1]ÜDM sahələr üzrə'!AO6 -> 0.97038857
B6: deflyator | C6: ÜDM deflyatoru | D6: % | E6: ='[1]ÜDM sahələr üzrə'!AI7 -> -1.4031027 | F6: ='[1]ÜDM sahələr üzrə'!AO7 -> 4.6446213 | G6: DSK (stat.gov.az / ASİS)
A7: 2. | B7: Neft-qaz sektoru, ÜDM, bazar qiymətləri ilə | C7: Neft-qaz sektoru üzrə ÜDM (bazar qiymətləri ilə) | D7: mln AZN | E7: ='[1]ÜDM sahələr üzrə'!AI366 -> 40624.6 | F7: ='[1]ÜDM sahələr üzrə'!AO366 -> 32416.158 | G7: DSK (stat.gov.az / ASİS)
B8: real artım tempi | C8: Real artım tempi | D8: % | E8: ='[1]ÜDM sahələr üzrə'!AI367 -> 0.25228338 | F8: ='[1]ÜDM sahələr üzrə'!AO367 -> -1.0913633
B9: deflyator | C9: Deflyator | D9: % | E9: ='[1]ÜDM sahələr üzrə'!AI368 -> -8.1918596 | F9: ='[1]ÜDM sahələr üzrə'!AO368 -> 1.1990834
B10: payı (ÜDM-də) | C10: ÜDM-də xüsusi çəkisi | D10: % | E10: =E7/E4*100 -> 32.15574 | F10: =F7/F4*100 -> 19.250306 | G10: DSK (stat.gov.az / ASİS)
A11: 3. | B11: Qeyri neft-qaz sektoru, ÜDM, bazar qiymətləri ilə | C11: Qeyri-neft-qaz sektoru üzrə ÜDM (bazar qiymətləri ilə) | D11: mln AZN | E11: ='[1]ÜDM sahələr üzrə'!AI363 -> 85712.41 | F11: ='[1]ÜDM sahələr üzrə'!AO363 -> 135976.79 | G11: DSK; AMB
B12: real artım tempi | C12: Real artım tempi | D12: % | E12: ='[1]ÜDM sahələr üzrə'!AI364 -> 6.1970718 | F12: ='[1]ÜDM sahələr üzrə'!AO364 -> 1.4961981
B13: deflyator | C13: Deflyator | D13: % | E13: ='[1]ÜDM sahələr üzrə'!AI365 -> 2.177958 | F13: ='[1]ÜDM sahələr üzrə'!AO365 -> 5.5009362
B14: payı (ÜDM-də) | C14: ÜDM-də xüsusi çəkisi | D14: % | E14: =E11/E4*100 -> 67.84426 | F14: =F11/F4*100 -> 80.749694 | G14: DSK (stat.gov.az / ASİS)

Sheet 2.4.1.2.
A1: Ümumi Daxili Məhsulun istehsal strukturu (onların artım və deflyator indeksləri, ümumi buraxılışı, aralıq istehlakı, əlavə dəyəri)
A2: № | B2: Göstəricilər | C2: ASİS-də olan ad | D2: Ölçü vahidi | G2: Mənbə / qeyd
E3: 2024 | F3: 2030
A4: 1. | B4: Kənd, meşə və balıqçılıq təsərrüfatı | C4: Kənd təsərrüfatı, meşə təsərrüfatı və balıqçılıq | G4: DSK (stat.gov.az / ASİS)
A5: a | B5: ümumi buraxılış | C5: Ümumi buraxılış | D5: mln AZN | E5: ='[1]ÜDM sahələr üzrə'!AI260 -> 13949.2 | F5: ='[1]ÜDM sahələr üzrə'!AO260 -> 17857.038
A6: b | B6: aralıq istehlak | C6: Aralıq istehlak | D6: mln AZN | E6: ='[1]ÜDM sahələr üzrə'!AI261 -> 6802.1 | F6: ='[1]ÜDM sahələr üzrə'!AO261 -> 8707.6935
A7: c | B7: əlavə dəyər | C7: Əlavə dəyər | D7: mln AZN | E7: ='[1]ÜDM sahələr üzrə'!AI262 -> 7147.1 | F7: ='[1]ÜDM sahələr üzrə'!AO262 -> 9149.3445
B8: əlavə dəyərin xüsusi çəkisi | C8: Əlavə dəyərin xüsusi çəkisi | D8: % | E8: ='[1]ÜDM sahələr üzrə'!AI263 -> 51.23663 | F8: ='[1]ÜDM sahələr üzrə'!AO263 -> 51.23663
B9: real artım tempi | C9: Real artım tempi | D9: % | E9: ='[1]ÜDM sahələr üzrə'!AI264 -> 1.4 | F9: ='[1]ÜDM sahələr üzrə'!AO264 -> 1.0872394
B10: deflyator | C10: Deflyator | D10: % | E10: ='[1]ÜDM sahələr üzrə'!AI265 -> 3.8808874 | F10: ='[1]ÜDM sahələr üzrə'!AO265 -> 1.7186532
A11: 2. | B11: Mədənçıxarma sənayesi | C11: Mədənçıxarma sənayesi
A12: a | B12: ümumi buraxılış | C12: Ümumi buraxılış | D12: mln AZN | E12: ='[1]ÜDM sahələr üzrə'!AI25 -> 41179.5 | F12: ='[1]ÜDM sahələr üzrə'!AO25 -> 34261.72
A13: b | B13: aralıq istehlak | C13: Aralıq istehlak | D13: mln AZN | E13: ='[1]ÜDM sahələr üzrə'!AI26 -> 4043.5 | F13: ='[1]ÜDM sahələr üzrə'!AO26 -> 5051.9808
A14: c | B14: əlavə dəyər | C14: Əlavə dəyər | D14: mln AZN | E14: ='[1]ÜDM sahələr üzrə'!AI27 -> 37136 | F14: ='[1]ÜDM sahələr üzrə'!AO27 -> 29209.739
B15: əlavə dəyərin xüsusi çəkisi | C15: Əlavə dəyərin xüsusi çəkisi | D15: % | E15: ='[1]ÜDM sahələr üzrə'!AI28 -> 90.180794 | F15: ='[1]ÜDM sahələr üzrə'!AO28 -> 85.254737
B16: real artım tempi | C16: Real artım tempi | D16: % | E16: ='[1]ÜDM sahələr üzrə'!AI29 -> 0.81941832 | F16: ='[1]ÜDM sahələr üzrə'!AO29 -> -1.6208316
B17: deflyator | C17: Deflyator | D17: % | E17: ='[1]ÜDM sahələr üzrə'!AI30 -> -9.9346188 | F17: ='[1]ÜDM sahələr üzrə'!AO30 -> 0.78378695
A18: 2.1. | B18: Xam neft və təbii qaz hasilatı | C18: Xam neft və təbii qazın hasilatı | G18: DSK (stat.gov.az / ASİS)
A19: a | B19: ümumi buraxılış | C19: Ümumi buraxılış | D19: mln AZN | E19: ='[1]ÜDM sahələr üzrə'!AI33 -> 38009.6 | F19: ='[1]ÜDM sahələr üzrə'!AO33 -> 27258.694
A20: b | B20: aralıq istehlak | C20: Aralıq istehlak | D20: mln AZN | E20: ='[1]ÜDM sahələr üzrə'!AI34 -> 2793.9 | F20: ='[1]ÜDM sahələr üzrə'!AO34 -> 2003.6534
A21: c | B21: əlavə dəyər | C21: Əlavə dəyər | D21: mln AZN | E21: ='[1]ÜDM sahələr üzrə'!AI35 -> 35215.7 | F21: ='[1]ÜDM sahələr üzrə'!AO35 -> 25255.04
B22: əlavə dəyərin xüsusi çəkisi | C22: Əlavə dəyərin xüsusi çəkisi | D22: % | E22: ='[1]ÜDM sahələr üzrə'!AI36 -> 92.649489 | F22: ='[1]ÜDM sahələr üzrə'!AO36 -> 92.649489
B23: real artım tempi | C23: Real artım tempi | D23: % | E23: ='[1]ÜDM sahələr üzrə'!AI37 -> 1.095 | F23: ='[1]ÜDM sahələr üzrə'!AO37 -> -0.6842747
B24: deflyator | C24: Deflyator | D24: % | E24: ='[1]ÜDM sahələr üzrə'!AI38 -> -10.878354 | F24: ='[1]ÜDM sahələr üzrə'!AO38 -> 0.28505387
A25: 2.2. | B25: Metal filizlərinin hasilatı | C25: Metal filizlərinin hasilatı
A26: a | B26: ümumi buraxılış | C26: Ümumi buraxılış | D26: mln AZN | E26: ='[1]ÜDM sahələr üzrə'!AI40 -> 382.4 | F26: ='[1]ÜDM sahələr üzrə'!AO40 -> 2595.7405
A27: b | B27: aralıq istehlak | C27: Aralıq istehlak | D27: mln AZN | E27: ='[1]ÜDM sahələr üzrə'!AI41 -> 199.6 | F27: ='[1]ÜDM sahələr üzrə'!AO41 -> 1354.8896
A28: c | B28: əlavə dəyər | C28: Əlavə dəyər | D28: mln AZN | E28: ='[1]ÜDM sahələr üzrə'!AI42 -> 182.8 | F28: ='[1]ÜDM sahələr üzrə'!AO42 -> 1240.8508
B29: əlavə dəyərin xüsusi çəkisi | C29: Əlavə dəyərin xüsusi çəkisi | D29: % | E29: ='[1]ÜDM sahələr üzrə'!AI43 -> 47.803347 | F29: ='[1]ÜDM sahələr üzrə'!AO43 -> 47.803347
B30: real artım tempi | C30: Real artım tempi | D30: % | E30: ='[1]ÜDM sahələr üzrə'!AI44 -> -11.2 | F30: ='[1]ÜDM sahələr üzrə'!AO44 -> -11.3168
B31: deflyator | C31: Deflyator | D31: % | E31: ='[1]ÜDM sahələr üzrə'!AI45 -> 29.632151 | F31: ='[1]ÜDM sahələr üzrə'!AO45 -> 0
A32: 2.3. | B32: Mədənçıxarma sənayesinin digər sahələri | C32: Mədənçıxarma sənayesinin digər sahələri
A33: a | B33: ümumi buraxılış | C33: Ümumi buraxılış | D33: mln AZN | E33: ='[1]ÜDM sahələr üzrə'!AI47 -> 256.7 | F33: ='[1]ÜDM sahələr üzrə'!AO47 -> 569.89595
A34: b | B34: aralıq istehlak | C34: Aralıq istehlak | D34: mln AZN | E34: ='[1]ÜDM sahələr üzrə'!AI48 -> 144 | F34: ='[1]ÜDM sahələr üzrə'!AO48 -> 319.69231
A35: c | B35: əlavə dəyər | C35: Əlavə dəyər | D35: mln AZN | E35: ='[1]ÜDM sahələr üzrə'!AI49 -> 112.7 | F35: ='[1]ÜDM sahələr üzrə'!AO49 -> 250.20364
B36: əlavə dəyərin xüsusi çəkisi | C36: Əlavə dəyərin xüsusi çəkisi | D36: % | E36: ='[1]ÜDM sahələr üzrə'!AI50 -> 43.903389 | F36: ='[1]ÜDM sahələr üzrə'!AO50 -> 43.903389
B37: real artım tempi | C37: Real artım tempi | D37: % | E37: ='[1]ÜDM sahələr üzrə'!AI51 -> 35.7 | F37: ='[1]ÜDM sahələr üzrə'!AO51 -> 7.8938796
B38: deflyator | C38: Deflyator | D38: % | E38: ='[1]ÜDM sahələr üzrə'!AI52 -> -18.776677 | F38: ='[1]ÜDM sahələr üzrə'!AO52 -> 7.2035648
A39: 2.4. | B39: Mədənçıxarma sənayesi sahəsinə xidmətlərin göstərilməsi | C39: Mədənçıxarma sənayesi sahəsinə xidmətlərin göstərilməsi | G39: Rəsmi adı dəqiqləşdirilməlidir (açıq mənbədə tapılmadı)
A40: a | B40: ümumi buraxılış | C40: Ümumi buraxılış | D40: mln AZN | E40: ='[1]ÜDM sahələr üzrə'!AI54 -> 2530.8 | F40: ='[1]ÜDM sahələr üzrə'!AO54 -> 3837.3896
...

Sheet 2.4.1.3.
A1: Ümumi Daxili Məhsulun sahə strukturu
A2: № | B2: Göstəricilər | C2: ASİS-də olan ad | D2: Ölçü vahidi | G2: Mənbə / qeyd
E3: 2024 | F3: 2030
A4: 1. | B4: Kənd, meşə və balıqçılıq təsərrüfatı | C4: Kənd təsərrüfatı, meşə təsərrüfatı və balıqçılıq | D4: ÜDM-də payı, % | E4: =E5/'2.4.1.1.'!E$4*100 -> 5.6571705 | F4: =F5/'2.4.1.1.'!F$4*100 -> 5.43333 | G4: DSK (stat.gov.az / ASİS)
B5: əlavə dəyər | C5: Əlavə dəyər | D5: mln AZN | E5: ='2.4.1.2.'!E7 -> 7147.1 | F5: ='2.4.1.2.'!F7 -> 9149.3445
B6: real artım tempi | C6: Real artım tempi | D6: % | E6: ='2.4.1.2.'!E9 -> 1.4 | F6: ='2.4.1.2.'!F9 -> 1.0872394
B7: deflyator | C7: Deflyator | D7: % | E7: ='2.4.1.2.'!E10 -> 3.8808874 | F7: ='2.4.1.2.'!F10 -> 1.7186532
A8: 2. | B8: Sənaye | C8: Sənaye | D8: ÜDM-də payı, % | E8: =E9/'2.4.1.1.'!E$4*100 -> 35.901285 | F8: =F9/'2.4.1.1.'!F$4*100 -> 25.521463
B9: əlavə dəyər | C9: Əlavə dəyər | D9: mln AZN | E9: ='[1]ÜDM sahələr üzrə'!AI12 -> 45356.61 | F9: ='[1]ÜDM sahələr üzrə'!AO12 -> 42976.343
B10: real artım tempi | C10: Real artım tempi | D10: % | E10: ='[1]ÜDM sahələr üzrə'!AI14 -> 0.94674976 | F10: ='[1]ÜDM sahələr üzrə'!AO14 -> -0.39202719
B11: deflyator | C11: Deflyator | D11: % | E11: ='[1]ÜDM sahələr üzrə'!AI15 -> -7.9461802 | F11: ='[1]ÜDM sahələr üzrə'!AO15 -> 1.5378257
A12: 2.1. | B12: Neft və qaz sənayesi | C12: Neft-qaz sənayesi | D12: ÜDM-də payı, % | E12: =E13/'2.4.1.1.'!E$4*100 -> 30.583358 | F12: =F13/'2.4.1.1.'!F$4*100 -> 18.308987 | G12: DSK (stat.gov.az / ASİS)
B13: əlavə dəyər | C13: Əlavə dəyər | D13: mln AZN | E13: ='[1]ÜDM sahələr üzrə'!AI71 -> 38638.1 | F13: ='[1]ÜDM sahələr üzrə'!AO71 -> 30831.042
B14: real artım tempi | C14: Real artım tempi | D14: % | E14: ='[1]ÜDM sahələr üzrə'!AI73 -> 0.32330243 | F14: ='[1]ÜDM sahələr üzrə'!AO73 -> -1.0913633
B15: deflyator | C15: Deflyator | D15: % | E15: ='[1]ÜDM sahələr üzrə'!AI74 -> -8.8994329 | F15: ='[1]ÜDM sahələr üzrə'!AO74 -> 1.1990834
A16: 2.2. | B16: Qeyri-neft-qaz sənayesi | C16: Qeyri-neft-qaz sənayesi | D16: ÜDM-də payı, % | E16: =E17/'2.4.1.1.'!E$4*100 -> 5.317927 | F16: =F17/'2.4.1.1.'!F$4*100 -> 7.2124762
B17: əlavə dəyər | C17: Əlavə dəyər | D17: mln AZN | E17: ='[1]ÜDM sahələr üzrə'!AI20 -> 6718.5099 | F17: ='[1]ÜDM sahələr üzrə'!AO20 -> 12145.301
B18: real artım tempi | C18: Real artım tempi | D18: % | E18: ='[1]ÜDM sahələr üzrə'!AI22 -> 4.9806449 | F18: ='[1]ÜDM sahələr üzrə'!AO22 -> 1.4506263
B19: deflyator | C19: Deflyator | D19: % | E19: ='[1]ÜDM sahələr üzrə'!AI23 -> -2.0519724 | F19: ='[1]ÜDM sahələr üzrə'!AO23 -> 2.4080007
A20: 3. | B20: Tikinti | C20: Tikinti | D20: ÜDM-də payı, % | E20: =E21/'2.4.1.1.'!E$4*100 -> 6.7107018 | F20: =F21/'2.4.1.1.'!F$4*100 -> 6.7096002
B21: əlavə dəyər | C21: Əlavə dəyər | D21: mln AZN | E21: ='[1]ÜDM sahələr üzrə'!AI271 -> 8478.1 | F21: ='[1]ÜDM sahələr üzrə'!AO271 -> 11298.493
B22: real artım tempi | C22: Real artım tempi | D22: % | E22: ='[1]ÜDM sahələr üzrə'!AI273 -> 9.6 | F22: ='[1]ÜDM sahələr üzrə'!AO273 -> -6.8641012
B23: deflyator | C23: Deflyator | D23: % | E23: ='[1]ÜDM sahələr üzrə'!AI276 -> 1.3374473 | F23: ='[1]ÜDM sahələr üzrə'!AO276 -> 3.8725136
A24: 4. | B24: Xidmətlərin istehsalı | C24: Xidmətlərin istehsalı | D24: ÜDM-də payı, % | E24: =E25/'2.4.1.1.'!E$4*100 -> 41.945033 | F24: =F25/'2.4.1.1.'!F$4*100 -> 52.236715
B25: əlavə dəyər | C25: Əlavə dəyər | D25: mln AZN | E25: ='[1]ÜDM sahələr üzrə'!AI282 -> 52992.1 | F25: ='[1]ÜDM sahələr üzrə'!AO282 -> 87962.943
B26: real artım tempi | C26: Real artım tempi | D26: % | E26: ='[1]ÜDM sahələr üzrə'!AI284 -> 6.4173413 | F26: ='[1]ÜDM sahələr üzrə'!AO284 -> 2.7671018
B27: deflyator | C27: Deflyator | D27: % | E27: ='[1]ÜDM sahələr üzrə'!AI285 -> 2.6086468 | F27: ='[1]ÜDM sahələr üzrə'!AO285 -> 6.8473652
A28: 4.1 | B28: Ticarət; nəqliyyat vasitələrinin təmiri | C28: Ticarət; nəqliyyat vasitələrinin təmiri | D28: ÜDM-də payı, % | E28: =E29/'2.4.1.1.'!E$4*100 -> 10.695678 | F28: =F29/'2.4.1.1.'!F$4*100 -> 14.126831
B29: əlavə dəyər | C29: Əlavə dəyər | D29: mln AZN | E29: ='[1]ÜDM sahələr üzrə'!AI289 -> 13512.6 | F29: ='[1]ÜDM sahələr üzrə'!AO289 -> 23788.587
B30: real artım tempi | C30: Real artım tempi | D30: % | E30: ='[1]ÜDM sahələr üzrə'!AI291 -> 3.8 | F30: ='[1]ÜDM sahələr üzrə'!AO291 -> 3.9111247
B31: deflyator | C31: Deflyator | D31: % | E31: ='[1]ÜDM sahələr üzrə'!AI294 -> 1.334364 | F31: ='[1]ÜDM sahələr üzrə'!AO294 -> 7.2035648
A32: 4.2 | B32: Turistlərin yerləşdirilməsi və ictimai iaşə | C32: Turistlərin yerləşdirilməsi və ictimai iaşə | D32: ÜDM-də payı, % | E32: =E33/'2.4.1.1.'!E$4*100 -> 2.4444935 | F32: =F33/'2.4.1.1.'!F$4*100 -> 2.152894
B33: əlavə dəyər | C33: Əlavə dəyər | D33: mln AZN | E33: ='[1]ÜDM sahələr üzrə'!AI300 -> 3088.3 | F33: ='[1]ÜDM sahələr üzrə'!AO300 -> 3625.3216
B34: real artım tempi | C34: Real artım tempi | D34: % | E34: ='[1]ÜDM sahələr üzrə'!AI302 -> 12.9 | F34: ='[1]ÜDM sahələr üzrə'!AO302 -> 6.5797348
B35: deflyator | C35: Deflyator | D35: % | E35: ='[1]ÜDM sahələr üzrə'!AI305 -> 2.2399396 | F35: ='[1]ÜDM sahələr üzrə'!AO305 -> 7.0659167
A36: 4.3 | B36: Nəqliyyat və anbar təsərrüfatı | C36: Nəqliyyat və anbar təsərrüfatı | D36: ÜDM-də payı, % | E36: =E37/'2.4.1.1.'!E$4*100 -> 6.9836226 | F36: =F37/'2.4.1.1.'!F$4*100 -> 9.0091781
B37: əlavə dəyər | C37: Əlavə dəyər | D37: mln AZN | E37: ='[1]ÜDM sahələr üzrə'!AI311 -> 8822.9 | F37: ='[1]ÜDM sahələr üzrə'!AO311 -> 15170.82
B38: real artım tempi | C38: Real artım tempi | D38: % | E38: ='[1]ÜDM sahələr üzrə'!AI313 -> 14.1 | F38: ='[1]ÜDM sahələr üzrə'!AO313 -> 0.55273522
B39: deflyator | C39: Deflyator | D39: % | E39: ='[1]ÜDM sahələr üzrə'!AI314 -> -1.2060434 | F39: ='[1]ÜDM sahələr üzrə'!AO314 -> 9.4134077
A40: 4.4 | B40: İnformasiya və rabitə | C40: İnformasiya və rabitə | D40: ÜDM-də payı, % | E40: =E41/'2.4.1.1.'!E$4*100 -> 1.8992851 | F40: =F41/'2.4.1.1.'!F$4*100 -> 2.5460893
...

Sheet 2.4.1.4.
A1: Azərbaycan Respublikasında istehsal olunan əsas məhsul növlərinin sahələr üzrə natural göstəricilərinin proqnozu (o cümlədən aksizli məhsulların növləri üzrə)
A2: № | B2: Göstəricilər | C2: ASİS-də olan ad | D2: Ölçü vahidi | G2: Mənbə / qeyd
E3: 2024 | F3: 2030
A4: 1. | B4: Kənd, meşə və balıqçılıq təsərrüfatı | C4: Kənd təsərrüfatı, meşə təsərrüfatı və balıqçılıq | G4: DSK (stat.gov.az / ASİS)
A5: 1.1 | B5: Bitkiçilik sahəsi | C5: Bitkiçilik | G5: DSK (stat.gov.az / ASİS)
B6: Dənli və dənli paxlalılar | C6: Dənli və dənli paxlalı bitkilər | D6: min ton | E6: ='[2]4_'!AI8 -> 3278.1 | F6: ='[2]4_'!AO8 -> 3448.11 | G6: DSK (stat.gov.az / ASİS)
B7: o cümlədən, buğda | C7: o cümlədən, buğda | D7: min ton | E7: ='[2]4_'!AI9 -> 1685.7 | F7: ='[2]4_'!AO9 -> 1684.8
B8: o cümlədən, çəltik | C8: o cümlədən, çəltik | D8: min ton | E8: ='[2]4_'!AI10 -> 19.6 | F8: ='[2]4_'!AO10 -> 20.96
B9: Tərəvəz | C9: Tərəvəz | D9: min ton | E9: ='[2]4_'!AI11 -> 1838.9 | F9: ='[2]4_'!AO11 -> 2022.5
B10: Bostan | C10: Bostan bitkiləri | D10: min ton | E10: ='[2]4_'!AI12 -> 490.6 | F10: ='[2]4_'!AO12 -> 539.72 | G10: DSK (stat.gov.az / ASİS)
B11: Kartof | C11: Kartof | D11: min ton | E11: ='[2]4_'!AI13 -> 927.4 | F11: ='[2]4_'!AO13 -> 1142.2
B12: Pambıq | C12: Pambıq | D12: min ton | E12: ='[2]4_'!AI14 -> 310.8 | F12: ='[2]4_'!AO14 -> 316.725
B13: Tütün | C13: Tütün | D13: min ton | E13: ='[2]4_'!AI15 -> 6.5 | F13: ='[2]4_'!AO15 -> 6.7375 | G13: DSK (stat.gov.az / ASİS)
B14: Şəkər çuğunduru | C14: Şəkər çuğunduru | D14: min ton | E14: ='[2]4_'!AI16 -> 290.1 | F14: ='[2]4_'!AO16 -> 318.24
B15: Dən üçün günəbaxan | C15: Dən üçün günəbaxan | D15: min ton | E15: ='[2]4_'!AI17 -> 31.2 | F15: ='[2]4_'!AO17 -> 33.7
B16: Meyvə və giləmeyvə | C16: Meyvə və giləmeyvə | D16: min ton | E16: ='[2]4_'!AI18 -> 1317.9 | F16: ='[2]4_'!AO18 -> 1516.08
B17: Üzüm | C17: Üzüm | D17: min ton | E17: ='[2]4_'!AI19 -> 205.1 | F17: ='[2]4_'!AO19 -> 216.98
B18: Çay yarpağı | C18: Yaşıl çay yarpağı | D18: min ton | E18: ='[2]4_'!AI20 -> 1.0695 | F18: ='[2]4_'!AO20 -> 1.26 | G18: DSK (stat.gov.az / ASİS)
A19: 1.2 | B19: Heyvandarlıq sahəsi | C19: Heyvandarlıq | G19: DSK (stat.gov.az / ASİS)
B20: Ət (diri çəkidə) | C20: Ət (diri çəkidə) | D20: min ton | E20: ='[2]4_'!AI22 -> 659 | F20: ='[2]4_'!AO22 -> 741.82087
B21: o cümlədən mal əti | C21: o cümlədən mal əti | D21: min ton | E21: ='[2]4_'!AI23 -> 272 | F21: ='[2]4_'!AO23 -> 297.72438
B22: o cümlədən qoyun əti | C22: o cümlədən qoyun və keçi əti | D22: min ton | E22: ='[2]4_'!AI24 -> 185.9 | F22: ='[2]4_'!AO24 -> 195.913 | G22: DSK (stat.gov.az / ASİS)
B23: o cümlədən quş əti | C23: o cümlədən quş əti | D23: min ton | E23: ='[2]4_'!AI25 -> 200.4 | F23: ='[2]4_'!AO25 -> 247.35033
B24: Yumurta | C24: Yumurta | D24: mln ədəd | E24: ='[2]4_'!AI26 -> 2300.8 | F24: ='[2]4_'!AO26 -> 2728.3341
B25: Süd (fiziki çəkidə) | C25: Süd (fiziki çəkidə) | D25: min ton | E25: ='[2]4_'!AI27 -> 2298.5 | F25: ='[2]4_'!AO27 -> 2500.5105
B26: Yun (fiziki çəkidə) | C26: Yun (fiziki çəkidə) | D26: min ton | E26: ='[2]4_'!AI28 -> 14.8 | F26: ='[2]4_'!AO28 -> 15.721492
B27: Barama (yaş çəkidə) | C27: Barama (yaş çəkidə) | D27: ton | E27: ='[2]4_'!AI29 -> 239.4 | F27: ='[2]4_'!AO29 -> 280
B28: İri buynuzlu mal-qara | C28: İri buynuzlu mal-qara | D28: min baş | E28: ='[2]4_'!AI30 -> 2465.622 | F28: ='[2]4_'!AO30 -> 2537.9282
B29: İnək-camış | C29: İnək və camışlar | D29: min baş | E29: ='[2]4_'!AI31 -> 1224.201 | F29: ='[2]4_'!AO31 -> 1250.1269 | G29: DSK (stat.gov.az / ASİS)
B30: Qoyun və keçilər | C30: Qoyun və keçilər | D30: min baş | E30: ='[2]4_'!AI32 -> 6896.52 | F30: ='[2]4_'!AO32 -> 6931.0716
B31: Donuzlar | C31: Donuzlar | D31: min baş | E31: ='[2]4_'!AI33 -> 3.1 | F31: ='[2]4_'!AO33 -> 3.6602897
B32: Quş | C32: Quşlar | D32: mln baş | E32: ='[2]4_'!AI34 -> 29.3 | F32: ='[2]4_'!AO34 -> 29.6 | G32: DSK (stat.gov.az / ASİS)
A33: 2. | B33: Mədənçıxarma sənayesi | C33: Mədənçıxarma sənayesi
A34: 2.1. | B34: Xam neft və təbii qaz hasilatı | C34: Xam neft və təbii qaz hasilatı
B35: Neft hasilatı | C35: Neft (qaz kondensatı daxil olmaqla) hasilatı | D35: min ton | E35: ='[3]O&G'!AI6 -> 29052.201 | F35: ='[3]O&G'!AO6 -> 27282.868 | G35: DSK (stat.gov.az / ASİS)
B36: Qaz hasilatı | C36: Təbii qaz hasilatı | D36: mln m3 | E36: ='[3]O&G'!AI29 -> 50339.395 | F36: ='[3]O&G'!AO29 -> 48054.081 | G36: DSK (stat.gov.az / ASİS)
B37: əmtəəlik qaz | C37: Əmtəəlik qaz | D37: mln m3 | E37: ='[3]O&G'!AI47 -> 38608.1 | F37: ='[3]O&G'!AO47 -> 36528.806
A38: 2.2. | B38: Metal filizlərinin hasilatı | C38: Metal filizlərinin hasilatı
B39: Qızıl filizləri və konsentratları | C39: Qızıl filizləri və konsentratları | D39: kq | E39: ='[4]2.2 VAR'!X15 -> 2660.93 | F39: ='[4]2.2 VAR'!AD15 -> 4177.9531
B40: Mis filizləri | C40: Mis filizləri | D40: ton | E40: ='[4]2.2 VAR'!X17 -> 239.89 | F40: ='[4]2.2 VAR'!AD17 -> 27094.224
...

Sheet 2.4.1.5.-7.
A1: Neftin dünya bazarında qiyməti
A2: № | B2: Göstəricilər | C2: ASİS-də olan ad | D2: Ölçü vahidi | G2: Mənbə / qeyd
E3: 2024 | F3: 2030
B4: Neftin qiyməti | C4: Neftin qiyməti | D4: USD/ barel | E4: =[1]IN!AI5 -> 80.7 | F4: =[1]IN!AO5 -> 65
A6: Əsas kapitala daxili və xarici investisiyalar (strukturu və real artım sürətləri)
A7: № | B7: Göstəricilər | C7: ASİS-də olan ad | D7: Ölçü vahidi | G7: Mənbə / qeyd
E8: =E3 -> 2024 | F8: 2030
A9: 1. | B9: Əsas kapitala cəmi investisiyalar | C9: Əsas kapitala yönəldilmiş investisiyalar – cəmi | D9: mln AZN | E9: =[1]Investisiya!AI5 -> 22106.3 | F9: =[1]Investisiya!AO5 -> 26850.745 | G9: DSK (stat.gov.az / ASİS)
B10: real artım tempi | C10: Real artım tempi | D10: % | E10: =[1]Investisiya!AI6 -> 2.4035326 | F10: =[1]Investisiya!AO6 -> -6.2716873
A11: 2. | B11: Daxili/Xarici | C11: Daxili / Xarici
A12: 2.1. | B12: Daxili investisiya | C12: Daxili mənbələrdən yönəldilmiş investisiyalar | D12: mln AZN | E12: =[1]Investisiya!AI8 -> 18774.7 | F12: =[1]Investisiya!AO8 -> 21565.088 | G12: DSK (stat.gov.az / ASİS)
B13: real artım tempi | C13: Real artım tempi | D13: % | E13: =[1]Investisiya!AI9 -> 6.46 | F13: =[1]Investisiya!AO9 -> -2.59553
B14: Cəmi investisiyalarda xüsusi çəkisi | C14: Cəmi investisiyalarda xüsusi çəkisi | D14: % | E14: =E12/E9*100 -> 84.929183 | F14: =F12/F9*100 -> 80.314675
A15: 2.2. | B15: Xarici investisiya | C15: Xarici mənbələrdən yönəldilmiş investisiyalar | D15: mln AZN | E15: =[1]Investisiya!AI10 -> 3331.6 | F15: =[1]Investisiya!AO10 -> 5285.6565 | G15: DSK (stat.gov.az / ASİS)
B16: real artım tempi | C16: Real artım tempi | D16: % | E16: =[1]Investisiya!AI11 -> -15.7 | F16: =[1]Investisiya!AO11 -> -18.778297
A17: 3. | B17: Neft/Qeyri neft-qaz | C17: Neft-qaz / qeyri-neft-qaz sektoru | G17: DSK (stat.gov.az / ASİS)
A18: 3.1. | B18: Neft və qaz sektoru | C18: Neft-qaz sektoru üzrə | D18: mln AZN | E18: =[1]Investisiya!AI12 -> 5852 | F18: =[1]Investisiya!AO12 -> 4663.9215 | G18: DSK (stat.gov.az / ASİS)
A19: 3.2. | B19: Digər sahələr | C19: Qeyri-neft-qaz sektoru üzrə | D19: mln AZN | E19: =[1]Investisiya!AI14 -> 16254.3 | F19: =[1]Investisiya!AO14 -> 22186.823
A20: 4. | B20: Dövlət/Qeyri-dövlət | C20: Mülkiyyət formaları üzrə: dövlət / qeyri-dövlət | G20: DSK (stat.gov.az / ASİS)
A21: 4.1. | B21: Dövlət | C21: Dövlət | D21: mln AZN | E21: =[1]Investisiya!AI16 -> 13352.9
B22: Cəmi investisiyalarda xüsusi çəkisi | C22: Cəmi investisiyalarda xüsusi çəkisi | D22: % | E22: =E15/E9*100 -> 15.070817
A23: 4.2. | B23: Qeyri-dövlət | C23: Qeyri-dövlət | D23: mln AZN | E23: =[1]Investisiya!AI18 -> 8753.4
A26: Əhalinin gəlirləri, xərcləri, orta aylıq əməkhaqqı, əhaliyə göstərilən ödənişli xidmətlər, məşğulluq və onların artım sürətləri
A27: № | B27: Göstəricilər | C27: ASİS-də olan ad | D27: Ölçü vahidi | G27: Mənbə / qeyd
E28: =E8 -> 2024 | F28: 2030
A29: 1. | B29: Gəlirlər | C29: Əhalinin nominal gəlirləri | D29: mln AZN | E29: ='[6]7_10'!AI6 -> 83093.4 | F29: ='[6]7_10'!AO6 -> 140165.6 | G29: DSK (stat.gov.az / ASİS)
B30: real artım tempi | C30: Real artım tempi | D30: illik, % | E30: ='[6]7_10'!AI7 -> 4.0710774 | F30: ='[6]7_10'!AO7 -> 1.6907043
A31: 2. | B31: Xərclər | C31: Əhalinin xərcləri | D31: mln AZN | E31: ='[6]7_10'!AI8 -> 81090.2 | F31: ='[6]7_10'!AO8 -> 134654.98 | G31: DSK (stat.gov.az / ASİS)
B32: real artım tempi | C32: Real artım tempi | D32: illik, % | E32: ='[6]7_10'!AI9 -> 3.7959292 | F32: ='[6]7_10'!AO9 -> 1.3726534
A33: 3. | B33: Orta aylıq əmək haqqı | C33: Orta aylıq nominal əməkhaqqı | D33: AZN | E33: ='[6]8'!AI7 -> 1009.2 | F33: ='[6]8'!AO7 -> 1522.5468 | G33: DSK (stat.gov.az / ASİS)
B34: real artım tempi | C34: Real artım tempi | D34: % | E34: ='[6]8'!AI8 -> 5.7367532 | F34: ='[6]8'!AO8 -> -0.57559653
A35: 3.1. | B35: Neft/qeyri-neft: | C35: Neft-qaz / qeyri-neft-qaz sektoru: | G35: DSK (stat.gov.az / ASİS)
B36: Neft | C36: Neft-qaz sektorunda | D36: AZN | E36: ='[6]8'!AI58 -> 3729.4 | F36: ='[6]8'!AO58 -> 3861.8772 | G36: DSK (stat.gov.az / ASİS)
B37: real artım tempi | C37: Real artım tempi | D37: % | E37: ='[6]8'!AI59 -> 4.0732217 | F37: ='[6]8'!AO59 -> -5.7762727
B38: Qeyri-neft | C38: Qeyri-neft-qaz sektorunda | D38: AZN | E38: ='[6]8'!AI60 -> 959.6 | F38: ='[6]8'!AO60 -> 1486.8574 | G38: DSK (stat.gov.az / ASİS)
B39: real artım tempi | C39: Real artım tempi | D39: % | E39: ='[6]8'!AI61 -> 6.0952823 | F39: ='[6]8'!AO61 -> -0.49215162
A40: 4. | B40: Əhaliyə göstərilən ödənişli xidmətlər | C40: Əhaliyə göstərilən ödənişli xidmətlər | D40: mln AZN | E40: ='[6]7_10'!AI11 -> 12885.5 | F40: ='[6]7_10'!AO11 -> 22229.865
B41: real artım tempi | C41: Real artım tempi | D41: illik, % | E41: ='[6]7_10'!AI12 -> 8.6 | F41: ='[6]7_10'!AO12 -> 3.3931008
A42: 5. | B42: Ümumi məşğulluq | C42: Məşğul əhalinin sayı | D42: min nəfər | E42: ='[6]9'!AI7 -> 5029.8 | F42: ='[6]9'!AO7 -> 5332.3364 | G42: DSK (stat.gov.az / ASİS)
B43: Artım tempi | C43: Artım tempi | D43: % | E43: ='[6]9'!AI8 -> 1.3398344 | F43: ='[6]9'!AO8 -> 0.66729072
...

Sheet 2.4.1.13.-14.
A1: Mal və xidmətlərin ticarət və tədiyə balansına görə idxalının və ixracının əsas göstəriciləri, onun strukturu (tədiyə balansı metodologiyası)
A2: № | B2: Göstəricilər | C2: ASİS-də olan ad | D2: Ölçü vahidi | G2: Mənbə / qeyd
E3: 2024
A4: 1. | B4: Malların ixracı | C4: Malların ixracı | D4: mln USD | E4: =[8]BOP!AI9 -> 25992.028
A5: 1.1 | B5: Neft və qaz | C5: Neft-qaz sektoru | D5: mln USD | E5: =[8]BOP!AI10 -> 22750.993 | G5: AMB (tədiyə balansı hesabatı)
A6: 1.2 | B6: Digər sektorlar | C6: Digər sektorlar | D6: mln USD | E6: =[8]BOP!AI11 -> 3241.035
A7: 2. | B7: Malların idxalı | C7: Malların idxalı | D7: mln USD | E7: =[8]BOP!AI12 -> 17167.084
A8: 2.1 | B8: Neft və qaz | C8: Neft-qaz sektoru | D8: mln USD | E8: =[8]BOP!AI13 -> 2468.831 | G8: AMB (tədiyə balansı hesabatı)
A9: 2.2 | B9: Digər sektorlar | C9: Digər sektorlar | D9: mln USD | E9: =[8]BOP!AI14 -> 14698.253
A10: 3. | B10: Xidmətlərin ixracı | C10: Xidmətlərin ixracı | D10: mln USD | E10: =[8]BOP!AI16 -> 8120.879
A11: 4. | B11: Xidmətlərin idxalı | C11: Xidmətlərin idxalı | D11: mln USD | E11: =[8]BOP!AI19 -> 10171.724
A12: 4.1 | B12: Neft və qaz | C12: Neft-qaz sektoru | D12: mln USD | E12: =[8]BOP!AI20 -> 3450.591 | G12: AMB (tədiyə balansı hesabatı)
A13: 4.2 | B13: Digər sektorlar | C13: Digər sektorlar | D13: mln USD | E13: =[8]BOP!AI21 -> 6721.133
A16: Cari əməliyyatlar hesabı
A17: № | B17: Göstəricilər | C17: ASİS-də olan ad | D17: Ölçü vahidi | G17: Mənbə / qeyd
A19: A. | B19: CARİ ƏMƏLİYYATLAR HESABI | C19: CARİ ƏMƏLİYYATLAR BALANSI | D19: mln USD | E19: =[8]BOP!AI4 -> 4671.108 | G19: AMB (tədiyə balansı hesabatı)
A20: A.1. | B20: XARİCİ TİCARƏT BALANSI | C20: XARİCİ TİCARƏT BALANSI | D20: mln USD | E20: =[8]BOP!AI8 -> 8824.944
B21: Neft-qaz sektoru | C21: Neft-qaz sektoru | D21: mln USD | E21: =[8]BOP!AI10-[8]BOP!AI13 -> 20282.162
B22: Digər sektorlar | C22: Digər sektorlar | D22: mln USD | E22: =[8]BOP!AI11-[8]BOP!AI14 -> -11457.218
A23: A2. | B23: XİDMƏTLƏR BALANSI | C23: XİDMƏTLƏR BALANSI | D23: mln USD | E23: =[8]BOP!AI15 -> -2050.845
B24: Neft-qaz sektoru | C24: Neft-qaz sektoru | D24: mln USD | E24: =[8]BOP!AI17-[8]BOP!AI20 -> -1843.056
B25: Digər sektorlar | C25: Digər sektorlar | D25: mln USD | E25: =[8]BOP!AI18-[8]BOP!AI21 -> -207.789
A26: A3. | B26: İLKİN GƏLİRLƏR | C26: İLKİN GƏLİRLƏR BALANSI | D26: mln USD | E26: =[8]BOP!AI22 -> -2734.735 | G26: AMB (tədiyə balansı hesabatı)
A27: A4. | B27: TƏKRAR GƏLİRLƏR | C27: TƏKRAR GƏLİRLƏR BALANSI | D27: mln USD | E27: =[8]BOP!AI29 -> 631.744 | G27: AMB (tədiyə balansı hesabatı)
A28: B | B28: KAPİTAL HESABI | C28: KAPİTAL HESABI | D28: mln USD | E28: =[8]BOP!AI33 -> -1.445
A29: C. | B29: MALİYYƏ HESABI | C29: MALİYYƏ HESABI | D29: mln USD | E29: =[8]BOP!AI36 -> -6628.8765
A30: C1. | B30: BİRBAŞA İNVESTİSİYALAR | C30: BİRBAŞA İNVESTİSİYALAR | D30: mln USD | E30: -878.27441
A31: C2. | B31: NEFT BONUSU | C31: NEFT BONUSU | D31: mln USD | E31: 450.2
A32: C3. | B32: PORTFEL İNVESTİSİYALARI | C32: PORTFEL İNVESTİSİYALARI | D32: mln USD | E32: -419.74567
A33: C4. | B33: TÖRƏMƏ MALİYYƏ ALƏTLƏRİ | C33: TÖRƏMƏ MALİYYƏ ALƏTLƏRİ | D33: mln USD | E33: 0
A34: C5. | B34: DİGƏR İNVESTİSİYALAR | C34: DİGƏR İNVESTİSİYALAR | D34: mln USD | E34: -1822.95
A35: D. | B35: EHTİYAT AKTİVLƏRİ | C35: EHTİYAT AKTİVLƏRİNİN DƏYİŞİMİ | D35: mln USD | E35: =-[8]BOP!AI57 -> -2065.8995 | G35: AMB (tədiyə balansı hesabatı)
A36: E. | B36: BALANSLAŞDIRICI MADDƏLƏR | C36: XALİS SƏHVLƏR VƏ BURAXILIŞLAR | D36: mln USD | E36: =[8]BOP!AI61 -> -106.686 | G36: AMB (tədiyə balansı hesabatı)
